Workbook

Sheet Dataset
A1: Customer ID | B1: First Name | C1: Last Name | D1: Age | E1: Gender | F1: Account Type | G1: Account Balance$ | H1: Annual Income$ | I1: Loan Status | J1: Loan Amount | K1: Credit Score | L1: Investment Type | M1: Credit Card Offers | N1: Online Banking Status | O1: Interest rate | P1: AI/LA | Q1: Check Num | R1: ODD EVEN check | S1: Rank | T1: Good(Active user | U1: Bad(Inactive User) | V1: Que 10 | W1: Hard Q2 | X1: Hard Q4 | Y1: Hard Q6 | Z1: Medium Q9
A2: 1 | B2: John | C2: Doe | D2: 44 | E2: M | F2: Checking | G2: 2500 | H2: 55000 | I2: No | J2: 0 | K2: 720 | L2: Stocks | M2: Premium | N2: Active | O2: 7 | P2: {=Dataset!H2:H350/Dataset!J2:J350} -> #DIV/0! | Q2: {=ISNUMBER(_xlfn.ANCHORARRAY(P2))} -> FALSE | R2: {=IF(MOD(D2:D350,2)=0,"Even","Odd")} -> Even | S2: =_xlfn.RANK.EQ(K2,K2:K350,0) -> 26 | T2: {=IF(N2:N350=N2,"Good","")} -> Good | U2: {=IF(N2:N350=N2,"","Bad")} | V2: {=ISTEXT(O2:O350)} -> FALSE | W2: {=IF(AND(D2:D350>40, K2:K350<300, H2:H350<8000), "Not Eligible", "Eligible")} -> Eligible | X2: =IF(AND(E2="M",K2>500,G2>2000),"Good", "Bad") -> Good | Y2: =IF(AND(M2<>"none",N2="Active"),"In Progress", "") -> In Progress | Z2: {=ISERROR(_xlfn.ANCHORARRAY(P2))} -> TRUE
A3: 2 | B3: Jane | C3: Smith | D3: 29 | E3: F | F3: Savings | G3: 8000 | H3: 62000 | I3: Yes | J3: 15000 | K3: 680 | L3: Bonds | M3: standard | N3: Inactive | O3: 5 | P3: 4.1333333 | Q3: TRUE | R3: Odd | S3: =_xlfn.RANK.EQ(K3,K3:K351,0) -> 253 | U3: Bad | V3: FALSE | W3: {=IF(AND(D3:D351>40, K3:K351<300, H3:H351<8000), "Not Eligible", "Eligible")} -> Eligible | X3: =IF(AND(E3="M",K3>500,G3>2000),"Good", "Bad") -> Bad | Y3: =IF(AND(M3<>"none",N3="Active"),"In Progress", "") | Z3: FALSE
A4: 3 | B4: Emily | C4: Johnson | D4: 45 | E4: F | F4: Checking | G4: 12000 | H4: 75000 | I4: No | J4: 0 | K4: 750 | L4: Mutual Funds | M4: none | N4: Active | O4: 3 | P4: #DIV/0! | Q4: FALSE | R4: Odd | S4: =_xlfn.RANK.EQ(K4,K4:K352,0) -> 1 | T4: Good | V4: FALSE | W4: {=IF(AND(D4:D352>40, K4:K352<300, H4:H352<8000), "Not Eligible", "Eligible")} -> Eligible | X4: =IF(AND(E4="M",K4>500,G4>2000),"Good", "Bad") -> Bad | Y4: =IF(AND(M4<>"none",N4="Active"),"In Progress", "") -> In Progress | Z4: TRUE
A5: 4 | B5: Michael | C5: Brown | D5: 52 | E5: M | F5: Savings | G5: 3000 | H5: 48000 | I5: Yes | J5: 5000 | K5: 690 | L5: Real Estate | M5: Premium | N5: Active | O5: 3 | P5: 9.6 | Q5: TRUE | R5: Even | S5: =_xlfn.RANK.EQ(K5,K5:K353,0) -> 192 | T5: Good | V5: FALSE | W5: {=IF(AND(D5:D353>40, K5:K353<300, H5:H353<8000), "Not Eligible", "Eligible")} -> Eligible | X5: =IF(AND(E5="M",K5>500,G5>2000),"Good", "Bad") -> Good | Y5: =IF(AND(M5<>"none",N5="Active"),"In Progress", "") -> In Progress | Z5: FALSE
A6: 5 | B6: Sarah | C6: Davis | D6: 37 | E6: F | F6: Checking | G6: 5000 | H6: 58000 | I6: No | J6: 0 | K6: 710 | L6: Stocks | M6: Premium | N6: Inactive | O6: 4 | P6: #DIV/0! | Q6: FALSE | R6: Odd | S6: =_xlfn.RANK.EQ(K6,K6:K354,0) -> 93 | U6: Bad | V6: FALSE | W6: {=IF(AND(D6:D354>40, K6:K354<300, H6:H354<8000), "Not Eligible", "Eligible")} -> Eligible | X6: =IF(AND(E6="M",K6>500,G6>2000),"Good", "Bad") -> Bad | Y6: =IF(AND(M6<>"none",N6="Active"),"In Progress", "") | Z6: TRUE
A7: 6 | B7: William | C7: Martinez | D7: 30 | E7: M | F7: Savings | G7: 6000 | H7: 70000 | I7: Yes | J7: 20000 | K7: 700 | L7: Bonds | M7: Premium | N7: Active | O7: 3 | P7: 3.5 | Q7: TRUE | R7: Even | S7: =_xlfn.RANK.EQ(K7,K7:K355,0) -> 144 | T7: Good | V7: FALSE | W7: {=IF(AND(D7:D355>40, K7:K355<300, H7:H355<8000), "Not Eligible", "Eligible")} -> Eligible | X7: =IF(AND(E7="M",K7>500,G7>2000),"Good", "Bad") -> Good | Y7: =IF(AND(M7<>"none",N7="Active"),"In Progress", "") -> In Progress | Z7: FALSE
A8: 7 | B8: Olivia | C8: Lee | D8: 40 | E8: F | F8: Checking | G8: 15000 | H8: 82000 | I8: No | J8: 0 | K8: 730 | L8: Mutual Funds | M8: Premium | N8: Inactive | O8: 7 | P8: #DIV/0! | Q8: FALSE | R8: Even | S8: =_xlfn.RANK.EQ(K8,K8:K356,0) -> 20 | U8: Bad | V8: FALSE | W8: {=IF(AND(D8:D356>40, K8:K356<300, H8:H356<8000), "Not Eligible", "Eligible")} -> Eligible | X8: =IF(AND(E8="M",K8>500,G8>2000),"Good", "Bad") -> Bad | Y8: =IF(AND(M8<>"none",N8="Active"),"In Progress", "") | Z8: TRUE
A9: 8 | B9: James | C9: Wilson | D9: 25 | E9: M | F9: Savings | G9: 2000 | H9: 43000 | I9: No | J9: 0 | K9: 670 | L9: Real Estate | M9: standard | N9: Active | O9: 12 | P9: #DIV/0! | Q9: FALSE | R9: Odd | S9: =_xlfn.RANK.EQ(K9,K9:K357,0) -> 312 | T9: Good | V9: FALSE | W9: {=IF(AND(D9:D357>40, K9:K357<300, H9:H357<8000), "Not Eligible", "Eligible")} -> Eligible | X9: =IF(AND(E9="M",K9>500,G9>2000),"Good", "Bad") -> Bad | Y9: =IF(AND(M9<>"none",N9="Active"),"In Progress", "") -> In Progress | Z9: TRUE
A10: 9 | B10: Ava | C10: Anderson | D10: 31 | E10: F | F10: Checking | G10: 7000 | H10: 55000 | I10: Yes | J10: 10000 | K10: 720 | L10: Stocks | M10: standard | N10: Active | O10: 11 | P10: 5.5 | Q10: TRUE | R10: Odd | S10: =_xlfn.RANK.EQ(K10,K10:K358,0) -> 24 | T10: Good | V10: FALSE | W10: {=IF(AND(D10:D358>40, K10:K358<300, H10:H358<8000), "Not Eligible", "Eligible")} -> Eligible | X10: =IF(AND(E10="M",K10>500,G10>2000),"Good", "Bad") -> Bad | Y10: =IF(AND(M10<>"none",N10="Active"),"In Progress", "") -> In Progress | Z10: FALSE
A11: 10 | B11: Ethan | C11: Thomas | D11: 44 | E11: M | F11: Savings | G11: 11000 | H11: 65000 | I11: No | J11: 0 | K11: 740 | L11: Bonds | M11: none | N11: Inactive | O11: 3 | P11: #DIV/0! | Q11: FALSE | R11: Even | S11: =_xlfn.RANK.EQ(K11,K11:K359,0) -> 5 | U11: Bad | V11: FALSE | W11: {=IF(AND(D11:D359>40, K11:K359<300, H11:H359<8000), "Not Eligible", "Eligible")} -> Eligible | X11: =IF(AND(E11="M",K11>500,G11>2000),"Good", "Bad") -> Good | Y11: =IF(AND(M11<>"none",N11="Active"),"In Progress", "") | Z11: TRUE
A12: 11 | B12: Isabella | C12: White | D12: 28 | E12: F | F12: Checking | G12: 4500 | H12: 47000 | I12: No | J12: 0 | K12: 690 | L12: Mutual Funds | M12: Premium | N12: Active | O12: 3 | P12: #DIV/0! | Q12: FALSE | R12: Even | S12: =_xlfn.RANK.EQ(K12,K12:K360,0) -> 187 | T12: Good | V12: FALSE | W12: {=IF(AND(D12:D360>40, K12:K360<300, H12:H360<8000), "Not Eligible", "Eligible")} -> Eligible | X12: =IF(AND(E12="M",K12>500,G12>2000),"Good", "Bad") -> Bad | Y12: =IF(AND(M12<>"none",N12="Active"),"In Progress", "") -> In Progress | Z12: TRUE
A13: 12 | B13: Benjamin | C13: Harris | D13: 39 | E13: M | F13: Savings | G13: 10000 | H13: 72000 | I13: Yes | J13: 12000 | K13: 700 | L13: Real Estate | M13: none | N13: Active | O13: No loan | P13: 6 | Q13: TRUE | R13: Odd | S13: =_xlfn.RANK.EQ(K13,K13:K361,0) -> 141 | T13: Good | V13: TRUE | W13: {=IF(AND(D13:D361>40, K13:K361<300, H13:H361<8000), "Not Eligible", "Eligible")} -> Eligible | X13: =IF(AND(E13="M",K13>500,G13>2000),"Good", "Bad") -> Good | Y13: =IF(AND(M13<>"none",N13="Active"),"In Progress", "") -> In Progress | Z13: FALSE
A14: 13 | B14: Mia | C14: Clark | D14: 26 | E14: F | F14: Checking | G14: 3500 | H14: 53000 | I14: No | J14: 0 | K14: 680 | L14: Stocks | M14: standard | N14: Inactive | O14: 11 | P14: #DIV/0! | Q14: FALSE | R14: Even | S14: =_xlfn.RANK.EQ(K14,K14:K362,0) -> 244 | U14: Bad | V14: FALSE | W14: {=IF(AND(D14:D362>40, K14:K362<300, H14:H362<8000), "Not Eligible", "Eligible")} -> Eligible | X14: =IF(AND(E14="M",K14>500,G14>2000),"Good", "Bad") -> Bad | Y14: =IF(AND(M14<>"none",N14="Active"),"In Progress", "") | Z14: TRUE
A15: 14 | B15: Jacob | C15: Lewis | D15: 33 | E15: M | F15: Savings | G15: 8000 | H15: 60000 | I15: Yes | J15: 8000 | K15: 710 | L15: Bonds | M15: Premium | N15: Active | O15: 11 | P15: 7.5 | Q15: TRUE | R15: Odd | S15: =_xlfn.RANK.EQ(K15,K15:K363,0) -> 90 | T15: Good | V15: FALSE | W15: {=IF(AND(D15:D363>40, K15:K363<300, H15:H363<8000), "Not Eligible", "Eligible")} -> Eligible | X15: =IF(AND(E15="M",K15>500,G15>2000),"Good", "Bad") -> Good | Y15: =IF(AND(M15<>"none",N15="Active"),"In Progress", "") -> In Progress | Z15: FALSE
A16: 15 | B16: Charlotte | C16: Walker | D16: 46 | E16: F | F16: Checking | G16: 13000 | H16: 85000 | I16: No | J16: 0 | K16: 740 | L16: Mutual Funds | M16: none | N16: Inactive | O16: 6 | P16: #DIV/0! | Q16: FALSE | R16: Even | S16: =_xlfn.RANK.EQ(K16,K16:K364,0) -> 5 | U16: Bad | V16: FALSE | W16: {=IF(AND(D16:D364>40, K16:K364<300, H16:H364<8000), "Not Eligible", "Eligible")} -> Eligible | X16: =IF(AND(E16="M",K16>500,G16>2000),"Good", "Bad") -> Bad | Y16: =IF(AND(M16<>"none",N16="Active"),"In Progress", "") | Z16: TRUE
A17: 16 | B17: Daniel | C17: Hall | D17: 52 | E17: M | F17: Savings | G17: 4000 | H17: 49000 | I17: Yes | J17: 7000 | K17: 690 | L17: Real Estate | M17: Premium | N17: Active | O17: 6 | P17: 7 | Q17: TRUE | R17: Even | S17: =_xlfn.RANK.EQ(K17,K17:K365,0) -> 184 | T17: Good | V17: FALSE | W17: {=IF(AND(D17:D365>40, K17:K365<300, H17:H365<8000), "Not Eligible", "Eligible")} -> Eligible | X17: =IF(AND(E17="M",K17>500,G17>2000),"Good", "Bad") -> Good | Y17: =IF(AND(M17<>"none",N17="Active"),"In Progress", "") -> In Progress | Z17: FALSE
A18: 17 | B18: Amelia | C18: Allen | D18: 24 | E18: M | F18: Checking | G18: 2200 | H18: 45000 | I18: No | J18: 0 | K18: 670 | L18: Stocks | M18: standard | N18: Inactive | O18: 5 | P18: #DIV/0! | Q18: FALSE | R18: Even | S18: =_xlfn.RANK.EQ(K18,K18:K366,0) -> 304 | U18: Bad | V18: FALSE | W18: {=IF(AND(D18:D366>40, K18:K366<300, H18:H366<8000), "Not Eligible", "Eligible")} -> Eligible | X18: =IF(AND(E18="M",K18>500,G18>2000),"Good", "Bad") -> Good | Y18: =IF(AND(M18<>"none",N18="Active"),"In Progress", "") | Z18: TRUE
A19: 18 | B19: Lucas | C19: Young | D19: 38 | E19: M | F19: Savings | G19: 15000 | H19: 77000 | I19: Yes | J19: 15000 | K19: 720 | L19: Bonds | M19: none | N19: Active | O19: No loan | P19: 5.1333333 | Q19: TRUE | R19: Even | S19: =_xlfn.RANK.EQ(K19,K19:K367,0) -> 22 | T19: Good | V19: TRUE | W19: {=IF(AND(D19:D367>40, K19:K367<300, H19:H367<8000), "Not Eligible", "Eligible")} -> Eligible | X19: =IF(AND(E19="M",K19>500,G19>2000),"Good", "Bad") -> Good | Y19: =IF(AND(M19<>"none",N19="Active"),"In Progress", "") -> In Progress | Z19: FALSE
A20: 19 | B20: Harper | C20: King | D20: 27 | E20: F | F20: Checking | G20: 4000 | H20: 50000 | I20: No | J20: 0 | K20: 680 | L20: Mutual Funds | M20: Premium | N20: Inactive | O20: 6 | P20: #DIV/0! | Q20: FALSE | R20: Odd | S20: =_xlfn.RANK.EQ(K20,K20:K368,0) -> 240 | U20: Bad | V20: FALSE | W20: {=IF(AND(D20:D368>40, K20:K368<300, H20:H368<8000), "Not Eligible", "Eligible")} -> Eligible | X20: =IF(AND(E20="M",K20>500,G20>2000),"Good", "Bad") -> Bad | Y20: =IF(AND(M20<>"none",N20="Active"),"In Progress", "") | Z20: TRUE
A21: 20 | B21: Alexander | C21: Scott | D21: 41 | E21: M | F21: Savings | G21: 9000 | H21: 69000 | I21: Yes | J21: 12000 | K21: 700 | L21: Real Estate | M21: none | N21: Active | O21: 5 | P21: 5.75 | Q21: TRUE | R21: Odd | S21: =_xlfn.RANK.EQ(K21,K21:K369,0) -> 138 | T21: Good | V21: FALSE | W21: {=IF(AND(D21:D369>40, K21:K369<300, H21:H369<8000), "Not Eligible", "Eligible")} -> Eligible | X21: =IF(AND(E21="M",K21>500,G21>2000),"Good", "Bad") -> Good | Y21: =IF(AND(M21<>"none",N21="Active"),"In Progress", "") -> In Progress | Z21: FALSE
A22: 21 | B22: Sophia | C22: Green | D22: 32 | E22: F | F22: Checking | G22: 5500 | H22: 54000 | I22: No | J22: 0 | K22: 710 | L22: Stocks | M22: Premium | N22: Inactive | O22: 14 | P22: #DIV/0! | Q22: FALSE | R22: Even | S22: =_xlfn.RANK.EQ(K22,K22:K370,0) -> 88 | U22: Bad | V22: FALSE | W22: {=IF(AND(D22:D370>40, K22:K370<300, H22:H370<8000), "Not Eligible", "Eligible")} -> Eligible | X22: =IF(AND(E22="M",K22>500,G22>2000),"Good", "Bad") -> Bad | Y22: =IF(AND(M22<>"none",N22="Active"),"In Progress", "") | Z22: TRUE
A23: 22 | B23: Henry | C23: Adams | D23: 47 | E23: M | F23: Savings | G23: 7000 | H23: 74000 | I23: Yes | J23: 10000 | K23: 690 | L23: Bonds | M23: standard | N23: Active | O23: 12 | P23: 7.4 | Q23: TRUE | R23: Odd | S23: =_xlfn.RANK.EQ(K23,K23:K371,0) -> 181 | T23: Good | V23: FALSE | W23: {=IF(AND(D23:D371>40, K23:K371<300, H23:H371<8000), "Not Eligible", "Eligible")} -> Eligible | X23: =IF(AND(E23="M",K23>500,G23>2000),"Good", "Bad") -> Good | Y23: =IF(AND(M23<>"none",N23="Active"),"In Progress", "") -> In Progress | Z23: FALSE
A24: 23 | B24: Ella | C24: Baker | D24: 35 | E24: F | F24: Checking | G24: 6000 | H24: 68000 | I24: No | J24: 0 | K24: 720 | L24: Mutual Funds | M24: standard | N24: Inactive | O24: 11 | P24: #DIV/0! | Q24: FALSE | R24: Odd | S24: =_xlfn.RANK.EQ(K24,K24:K372,0) -> 22 | U24: Bad | V24: FALSE | W24: {=IF(AND(D24:D372>40, K24:K372<300, H24:H372<8000), "Not Eligible", "Eligible")} -> Eligible | X24: =IF(AND(E24="M",K24>500,G24>2000),"Good", "Bad") -> Bad | Y24: =IF(AND(M24<>"none",N24="Active"),"In Progress", "") | Z24: TRUE
A25: 24 | B25: Jack | C25: Nelson | D25: 29 | E25: M | F25: Savings | G25: 2500 | H25: 45000 | I25: Yes | J25: 5000 | K25: 670 | L25: Real Estate | M25: standard | N25: Active | O25: 8 | P25: 9 | Q25: TRUE | R25: Odd | S25: =_xlfn.RANK.EQ(K25,K25:K373,0) -> 298 | T25: Good | V25: FALSE | W25: {=IF(AND(D25:D373>40, K25:K373<300, H25:H373<8000), "Not Eligible", "Eligible")} -> Eligible | X25: =IF(AND(E25="M",K25>500,G25>2000),"Good", "Bad") -> Good | Y25: =IF(AND(M25<>"none",N25="Active"),"In Progress", "") -> In Progress | Z25: FALSE
A26: 25 | B26: Grace | C26: Carter | D26: 42 | E26: F | F26: Checking | G26: 11000 | H26: 80000 | I26: No | J26: 0 | K26: 740 | L26: Stocks | M26: none | N26: Inactive | O26: 4 | P26: #DIV/0! | Q26: FALSE | R26: Even | S26: =_xlfn.RANK.EQ(K26,K26:K374,0) -> 5 | U26: Bad | V26: FALSE | W26: {=IF(AND(D26:D374>40, K26:K374<300, H26:H374<8000), "Not Eligible", "Eligible")} -> Eligible | X26: =IF(AND(E26="M",K26>500,G26>2000),"Good", "Bad") -> Bad | Y26: =IF(AND(M26<>"none",N26="Active"),"In Progress", "") | Z26: TRUE
A27: 26 | B27: Michael | C27: Mitchell | D27: 50 | E27: M | F27: Savings | G27: 3000 | H27: 47000 | I27: Yes | J27: 8000 | K27: 680 | L27: Bonds | M27: none | N27: Active | O27: 13 | P27: 5.875 | Q27: TRUE | R27: Even | S27: =_xlfn.RANK.EQ(K27,K27:K375,0) -> 235 | T27: Good | V27: FALSE | W27: {=IF(AND(D27:D375>40, K27:K375<300, H27:H375<8000), "Not Eligible", "Eligible")} -> Eligible | X27: =IF(AND(E27="M",K27>500,G27>2000),"Good", "Bad") -> Good | Y27: =IF(AND(M27<>"none",N27="Active"),"In Progress", "") -> In Progress | Z27: FALSE
A28: 27 | B28: Lily | C28: Roberts | D28: 28 | E28: F | F28: Checking | G28: 4000 | H28: 53000 | I28: No | J28: 0 | K28: 690 | L28: Mutual Funds | M28: Premium | N28: Inactive | O28: 7 | P28: #DIV/0! | Q28: FALSE | R28: Even | S28: =_xlfn.RANK.EQ(K28,K28:K376,0) -> 179 | U28: Bad | V28: FALSE | W28: {=IF(AND(D28:D376>40, K28:K376<300, H28:H376<8000), "Not Eligible", "Eligible")} -> Eligible | X28: =IF(AND(E28="M",K28>500,G28>2000),"Good", "Bad") -> Bad | Y28: =IF(AND(M28<>"none",N28="Active"),"In Progress", "") | Z28: TRUE
A29: 28 | B29: James | C29: Martinez | D29: 36 | E29: M | F29: Savings | G29: 9000 | H29: 71000 | I29: Yes | J29: 13000 | K29: 700 | L29: Real Estate | M29: standard | N29: Active | O29: 4 | P29: 5.4615385 | Q29: TRUE | R29: Even | S29: =_xlfn.RANK.EQ(K29,K29:K377,0) -> 135 | T29: Good | V29: FALSE | W29: {=IF(AND(D29:D377>40, K29:K377<300, H29:H377<8000), "Not Eligible", "Eligible")} -> Eligible | X29: =IF(AND(E29="M",K29>500,G29>2000),"Good", "Bad") -> Good | Y29: =IF(AND(M29<>"none",N29="Active"),"In Progress", "") -> In Progress | Z29: FALSE
A30: 29 | B30: Natalie | C30: Thompson | D30: 41 | E30: F | F30: Checking | G30: 8000 | H30: 67000 | I30: No | J30: 0 | K30: 710 | L30: Stocks | M30: none | N30: Inactive | O30: 14 | P30: #DIV/0! | Q30: FALSE | R30: Odd | S30: =_xlfn.RANK.EQ(K30,K30:K378,0) -> 86 | U30: Bad | V30: FALSE | W30: {=IF(AND(D30:D378>40, K30:K378<300, H30:H378<8000), "Not Eligible", "Eligible")} -> Eligible | X30: =IF(AND(E30="M",K30>500,G30>2000),"Good", "Bad") -> Bad | Y30: =IF(AND(M30<>"none",N30="Active"),"In Progress", "") | Z30: TRUE
A31: 30 | B31: Oliver | C31: Walker | D31: 30 | E31: M | F31: Savings | G31: 5000 | H31: 55000 | I31: Yes | J31: 7000 | K31: 690 | L31: Bonds | M31: none | N31: Active | O31: 5 | P31: 7.8571429 | Q31: TRUE | R31: Even | S31: =_xlfn.RANK.EQ(K31,K31:K379,0) -> 177 | T31: Good | V31: FALSE | W31: {=IF(AND(D31:D379>40, K31:K379<300, H31:H379<8000), "Not Eligible", "Eligible")} -> Eligible | X31: =IF(AND(E31="M",K31>500,G31>2000),"Good", "Bad") -> Good | Y31: =IF(AND(M31<>"none",N31="Active"),"In Progress", "") -> In Progress | Z31: FALSE
A32: 31 | B32: Ava | C32: Carter | D32: 29 | E32: F | F32: Checking | G32: 3000 | H32: 48000 | I32: No | J32: 0 | K32: 670 | L32: Mutual Funds | M32: Premium | N32: Inactive | O32: 10 | P32: #DIV/0! | Q32: FALSE | R32: Odd | S32: =_xlfn.RANK.EQ(K32,K32:K380,0) -> 292 | U32: Bad | V32: FALSE | W32: {=IF(AND(D32:D380>40, K32:K380<300, H32:H380<8000), "Not Eligible", "Eligible")} -> Eligible | X32: =IF(AND(E32="M",K32>500,G32>2000),"Good", "Bad") -> Bad | Y32: =IF(AND(M32<>"none",N32="Active"),"In Progress", "") | Z32: TRUE
A33: 32 | B33: Ethan | C33: Anderson | D33: 34 | E33: M | F33: Savings | G33: 11000 | H33: 62000 | I33: Yes | J33: 12000 | K33: 720 | L33: Real Estate | M33: Premium | N33: Active | O33: 10 | P33: 5.1666667 | Q33: TRUE | R33: Even | S33: =_xlfn.RANK.EQ(K33,K33:K381,0) -> 21 | T33: Good | V33: FALSE | W33: {=IF(AND(D33:D381>40, K33:K381<300, H33:H381<8000), "Not Eligible", "Eligible")} -> Eligible | X33: =IF(AND(E33="M",K33>500,G33>2000),"Good", "Bad") -> Good | Y33: =IF(AND(M33<>"none",N33="Active"),"In Progress", "") -> In Progress | Z33: FALSE
A34: 33 | B34: Mia | C34: Nelson | D34: 37 | E34: F | F34: Checking | G34: 5500 | H34: 69000 | I34: No | J34: 0 | K34: 710 | L34: Stocks | M34: Premium | N34: Inactive | O34: 7 | P34: #DIV/0! | Q34: FALSE | R34: Odd | S34: =_xlfn.RANK.EQ(K34,K34:K382,0) -> 85 | U34: Bad | V34: FALSE | W34: {=IF(AND(D34:D382>40, K34:K382<300, H34:H382<8000), "Not Eligible", "Eligible")} -> Eligible | X34: =IF(AND(E34="M",K34>500,G34>2000),"Good", "Bad") -> Bad | Y34: =IF(AND(M34<>"none",N34="Active"),"In Progress", "") | Z34: TRUE
A35: 34 | B35: Daniel | C35: Smith | D35: 45 | E35: M | F35: Checking | G35: 7000 | H35: 74000 | I35: Yes | J35: 15000 | K35: 680 | L35: Bonds | M35: Premium | N35: Active | O35: 5 | P35: 4.9333333 | Q35: TRUE | R35: Odd | S35: =_xlfn.RANK.EQ(K35,K35:K383,0) -> 229 | T35: Good | V35: FALSE | W35: {=IF(AND(D35:D383>40, K35:K383<300, H35:H383<8000), "Not Eligible", "Eligible")} -> Eligible | X35: =IF(AND(E35="M",K35>500,G35>2000),"Good", "Bad") -> Good | Y35: =IF(AND(M35<>"none",N35="Active"),"In Progress", "") -> In Progress | Z35: FALSE
A36: 35 | B36: Sophia | C36: Johnson | D36: 40 | E36: F | F36: Checking | G36: 2000 | H36: 50000 | I36: No | J36: 0 | K36: 720 | L36: Mutual Funds | M36: Premium | N36: Inactive | O36: 15 | P36: #DIV/0! | Q36: FALSE | R36: Even | S36: =_xlfn.RANK.EQ(K36,K36:K384,0) -> 21 | U36: Bad | V36: FALSE | W36: {=IF(AND(D36:D384>40, K36:K384<300, H36:H384<8000), "Not Eligible", "Eligible")} -> Eligible | X36: =IF(AND(E36="M",K36>500,G36>2000),"Good", "Bad") -> Bad | Y36: =IF(AND(M36<>"none",N36="Active"),"In Progress", "") | Z36: TRUE
A37: 36 | B37: William | C37: White | D37: 27 | E37: M | F37: Savings | G37: 6000 | H37: 55000 | I37: Yes | J37: 10000 | K37: 690 | L37: Real Estate | M37: Premium | N37: Active | O37: 4 | P37: 5.5 | Q37: TRUE | R37: Odd | S37: =_xlfn.RANK.EQ(K37,K37:K385,0) -> 174 | T37: Good | V37: FALSE | W37: {=IF(AND(D37:D385>40, K37:K385<300, H37:H385<8000), "Not Eligible", "Eligible")} -> Eligible | X37: =IF(AND(E37="M",K37>500,G37>2000),"Good", "Bad") -> Good | Y37: =IF(AND(M37<>"none",N37="Active"),"In Progress", "") -> In Progress | Z37: FALSE
A38: 37 | B38: Isabella | C38: Thompson | D38: 31 | E38: F | F38: Checking | G38: 3500 | H38: 62000 | I38: No | J38: 0 | K38: 680 | L38: Stocks | M38: none | N38: Inactive | O38: 15 | P38: #DIV/0! | Q38: FALSE | R38: Odd | S38: =_xlfn.RANK.EQ(K38,K38:K386,0) -> 227 | U38: Bad | V38: FALSE | W38: {=IF(AND(D38:D386>40, K38:K386<300, H38:H386<8000), "Not Eligible", "Eligible")} -> Eligible | X38: =IF(AND(E38="M",K38>500,G38>2000),"Good", "Bad") -> Bad | Y38: =IF(AND(M38<>"none",N38="Active"),"In Progress", "") | Z38: TRUE
A39: 38 | B39: Jacob | C39: Harris | D39: 53 | E39: M | F39: Savings | G39: 4000 | H39: 48000 | I39: Yes | J39: 5000 | K39: 710 | L39: Bonds | M39: none | N39: Active | O39: No loan | P39: 9.6 | Q39: TRUE | R39: Odd | S39: =_xlfn.RANK.EQ(K39,K39:K387,0) -> 84 | T39: Good | V39: TRUE | W39: {=IF(AND(D39:D387>40, K39:K387<300, H39:H387<8000), "Not Eligible", "Eligible")} -> Eligible | X39: =IF(AND(E39="M",K39>500,G39>2000),"Good", "Bad") -> Good | Y39: =IF(AND(M39<>"none",N39="Active"),"In Progress", "") -> In Progress | Z39: FALSE
A40: 39 | B40: Harper | C40: Adams | D40: 28 | E40: F | F40: Checking | G40: 5500 | H40: 59000 | I40: No | J40: 0 | K40: 700 | L40: Mutual Funds | M40: none | N40: Inactive | O40: 14 | P40: #DIV/0! | Q40: FALSE | R40: Even | S40: =_xlfn.RANK.EQ(K40,K40:K388,0) -> 130 | U40: Bad | V40: FALSE | W40: {=IF(AND(D40:D388>40, K40:K388<300, H40:H388<8000), "Not Eligible", "Eligible")} -> Eligible | X40: =IF(AND(E40="M",K40>500,G40>2000),"Good", "Bad") -> Bad | Y40: =IF(AND(M40<>"none",N40="Active"),"In Progress", "") | Z40: TRUE
...

Sheet Questions
B1: ASSIGNMENT INSTRUCTIONS :-
C3: Student should use different sheet for answering each topic for eg-Easy questions can be answered in one sheet & then Medium questions can be answered in another one, don't forget to name that sheet too.
C4: Student should provide question number above the solution. For eg- Easy- Answer 1
C5: Student should provide all the solution sheet in sequence.
C7: Easy
B9: Q1 | C9: As a junior manager, can you calculate the average annual income?
B10: Q2 | C10: Can you find the median of the bank account balances to help understand the middle value of the data?
B11: Q3 | C11: Your manager asked you to find the 5th smallest loan amount. Can you find the answer?
B12: Q4 | C12: Your task is to determine the 3rd highest credit score ?
B13: Q5 | C13: Before approving loans, the bank wants to check which credit score appears the most often. Can you find the credit score with the highest frequency
B14: Q6 | C14: You need to prepare a report on the number of females who are actively involved. To do this, find out how many account holders in your bank are female, over 30 years old, use online banking, and have a credit card.
B15: Q7 | C15: Take the annual income and divide it by the loan amount. If there is any problem while doing this, write 'Division Error' in a new column.
B16: Q8 | C16: In the 'Division Error' column, use a function to check if the values in the cells are numbers or not.
B17: Q9 | C17: Find out which consumers have an odd age and which have an even age. List these in separate columns
B18: Q10 | C18: What is the lowest account balance among customers who have a premium credit card?
B19: Q11 | C19: The bank wants to offer a new loan to people with good credit scores. Rank the people from highest to lowest credit score.
B20: Q12 | C20: Your team wants to know how many account holder we have so far. Can you figure out 1.)how many accounts there are in the dataset? 2.)what is the smallest account balance so far?
B21: Q13 | C21: As a banker, you need to give your manager a report .This report should include-the total annual income and account balance. Additionally, identify the maximum figure for both annual income and account balance.
C24: MEDIUM
B25: Q1 | C25: In the digital world, many people use online banking. You need to find out how many people have an active banking status and what their 50th percentile income will be.
B26: Q2 | C26: Your bank manager is curious to know how many people have taken out loans from the bank and what is the highest loan amount anyone has taken. Can you find this information?
B27: Q3 | C27: What is the 3rd smallest account balance among account holders who haven't taken out a loan?
B28: Q4 | C28: What is the fourth highest account balance in your bank for customers who have a premium membership?
B29: Q5 | C29: Find out how many women have bank accounts and what the second lowest annual income is among them
B30: Q6 | C30: To prepare the account balance report, first find the most common balance amount. Then, calculate the average of that column.
B31: Q7 | C31: Determine the 75th percentile for both annual income and account balance.
B32: Q8 | C32: To make the net banking report, first find out how many people use online banking. Then, group them into two categories: 'Good' for those who are active users and 'Bad' for those who are not active.
B33: Q9 | C33: Check for errors in the new 'Division Error' column. Use the ISERROR function to see if there are any mistakes.
B34: Q10 | C34: Use the right function to see if there's any text in the 'Interest rate' column.
B35: Q11 | C35: To analyze total deposit of the given dataset , first calculate the total annual income. Then, determine the 40th percentile of the annual income for people with odd ages.
B36: Q12 | C36: To evaluate customer investment, find out how many customers have an account balance over $5,000 and an annual income greater than $7,000. Label these customers as 'Active Consumers.
B37: Q13 | C37: Investing in a real estate is a good option. Can u determine how many people are investing in real estate, the total amount invested so far, and the highest amount of money invested by any one person.
C39: HARD
B40: Q1 | C40: How many female account holders have invested in mutual funds and have a credit score above 500? Also, what is the highest account balance among them?
B41: Q2 | C41: Identify account holders who are over 40, have a credit score below 300, and an annual income under $8,000. These individuals will not be offered new credit cards. Mark these account holders as "Not Eligible."
B42: Q3 | C42: What is the minimum account balance for female customers who are inactive in online banking? Additionally, how many females use online banking, and how many do not?
B43: Q4 | C43: For male account holders with checking accounts, whose balance is over $2,000 and credit score above 500, categorize them as "Good" consumers. All others should be categorized as "Bad."
B44: Q5 | C44: Your manager needs a report on the account holder with the highest income who has a savings account and is eligible for a credit card.
B45: Q6 | C45: In the market, there are very few consumers who accept every offer. Create a new column to categorize consumers as "In Progress" if they have accepted a credit card offer, made an investment, and are active in online banking.
B46: Q7 | C46: Using the conditions in question 6 above, find the second smallest annual income among the consumers.
...

Sheet Easy
A2: Ans 1 | B2: =AVERAGE(Dataset!H2:H350) -> 60260.745
A4: Ans 2 | B4: =MEDIAN(Dataset!G2:G350) -> 5500
A6: Ans 3 | B6: =SMALL(_xlfn.UNIQUE(Dataset!J2:J350),5) -> 8000
A8: Ans 4 | B8: =LARGE(_xlfn.UNIQUE(Dataset!K2:K350),3) -> 730
A10: Ans 5 | B10: {=_xlfn.MODE.MULT(Dataset!K2:K350)} -> 720
A12: Ans 6 | B12: =COUNTIFS(Dataset!E2:E350,Dataset!E324,Dataset!D2:D350,">30",Dataset!N2:N350,Dataset!N323,Dataset!M2:M350,"<>Dataset!M329") -> 8
A14: Ans 7 | B14: refer to dataset sheet column number P (AI/LA)
A16: Ans 8 | B16: Please refer to dataset column Q (CheckNum)
A18: Ans 9 | B18: Please refer to dataset column R (ODD Even Check)
A20: Ans 10 | B20: =_xlfn.MINIFS(Dataset!G2:G350,Dataset!M2:M350,Dataset!M330) -> 1500
A22: Ans 11 | B22: Please refer to dataset column S (Rank)
A24: Ans 12 | B24: 1. Total Dataset | D24: 2. Smalest Account Balance
B25: =COUNT(Dataset!A2:A350) -> 349 | D25: =MIN(Dataset!G2:G350) -> 1500
A27: Ans 13 | B27: Total Annual Income | D27: Total Account Balance
B28: =SUM(Dataset!H2:H350) -> 21031000 | D28: =SUM(Dataset!G2:G350) -> 2146000
B30: Max Annual Income | D30: Max Account Balance
B31: =MAX(Dataset!H2:H350) -> 85000 | D31: =MAX(Dataset!G2:G350) -> 15000

Sheet Medium
B1: total active user | C1: 50 % annual Income
A2: Ans 1 | B2: =COUNTIF(Dataset!N2:N350,Dataset!N327) -> 182 | C2: {=_xlfn.PERCENTILE.INC(IF(Dataset!N2:N350="Active",Dataset!H2:H350),0.5)} -> 60000
A4: Ans 2 | B4: People Taken Loan | C4: Highest loan amount
B5: =COUNTIF(Dataset!I2:I350,Dataset!I325) -> 169 | C5: =MAX(Dataset!J2:J350) -> 20000
A7: Ans 3
B8: {=SMALL(IF(Dataset!I2:I350="No",Dataset!G2:G350),3)} -> 1500
A9: Ans 4
B10: {=LARGE(_xlfn.UNIQUE(IF(Dataset!M2:M350=Dataset!M8,Dataset!G2:G350)),4)} -> 7000
A12: Ans 5 | B12: Women have Bank account | C12: 2nd lowest annual income UNIQUE
B13: =COUNTIF(Dataset!E2:E350,Dataset!E334) -> 170 | C13: {=SMALL(_xlfn.UNIQUE(IF(Dataset!E2:E350=Dataset!E332,Dataset!H2:H350)), 2)} -> 47000
A15: Ans 6 | B15: Common balance amount | C15: Average of Account Balance
B16: {=_xlfn.MODE.MULT(Dataset!G2:G350)} -> 4000 | C16: =AVERAGE(Dataset!G2:G350) -> 6148.9971
A18: Ans 7 | B18: Annual Income 75% | C18: 75% of Account balance
B19: =_xlfn.PERCENTILE.INC(Dataset!H2:H350,0.75) -> 70000 | C19: =_xlfn.PERCENTILE.INC(Dataset!G2:G350,0.75) -> 8000
A21: Ans 8 | B21: Online Banking User | C21: Good User | D21: Bad User
B22: =COUNTIF(Dataset!N2:N350,Dataset!N327) -> 182 | C22: =COUNTIF(Dataset!N2:N350,Dataset!N341) -> 182 | D22: =COUNTIF(Dataset!N2:N350,Dataset!N340) -> 167
A24: Ans 9
B25: please refer column Z (medium Q9)
A27: Ans 10 | B27: Please refer column V (Que 10)
A29: Ans 11 | B29: Total annual income | C29: 40th percentile of the annual income
B30: =SUM(Dataset!H2:H350) -> 21031000 | C30: {=_xlfn.PERCENTILE.INC(IF(MOD(Dataset!D2:D350,2)=1,Dataset!H2:H350), 0.4)} -> 55000
A32: Ans 12
B33: =COUNTIFS(Dataset!G2:G350,">5000",Dataset!H2:H350,">7000") -> 186
A35: Ans 13 | B35: How many people are investing in real state | C35: Total amount invested in Real State | D35: Highest amount invested in Real State
B36: =COUNTIF(Dataset!L2:L350,Dataset!L339) -> 86 | C36: =SUMIF(Dataset!L2:L350,Dataset!L327,Dataset!H2:H350) -> 5203000 | D36: =_xlfn.MAXIFS(Dataset!H2:H350,Dataset!L2:L350,Dataset!L331) -> 74000

Sheet Hard
A2: Ans 1
B3: =COUNTIFS(Dataset!E2:E350,Dataset!E324,Dataset!L2:L350,Dataset!L326,Dataset!K2:K350,">500") -> 87 | C3: =_xlfn.MAXIFS(Dataset!G2:G350,Dataset!E2:E350,Dataset!E324,Dataset!L2:L350,Dataset!L326,Dataset!K2:K350,">500") -> 15000
A5: Ans 2
B6: Please refer W column (Hard Q2)
A8: Ans 3 | C8: Female use online banking | D8: Female don’t use online banking
B9: =_xlfn.MINIFS(Dataset!G2:G350,Dataset!E2:E350,Dataset!E330,Dataset!N2:N350,Dataset!N326) -> 1500 | C9: =COUNTIFS(Dataset!E2:E350,Dataset!E326,Dataset!N2:N350,Dataset!N327) -> 13 | D9: =COUNTIFS(Dataset!E2:E350,Dataset!E326,Dataset!N2:N350,Dataset!N328) -> 157
A11: Ans 4
B12: Please refer column X (Hard Q4)
A14: Ans 5 | B14: =_xlfn.MAXIFS(Dataset!H2:H350,Dataset!F2:F350,"Savings",Dataset!M2:M350,Dataset!M328) -> 80000
A16: Ans 6 | B16: Please refer Column Y (Hard Q6)
A18: And 7
B19: {=SMALL(_xlfn._xlws.FILTER(Dataset!H2:H350,(Dataset!M2:M350<>"none")*(Dataset!N2:N350="Active")),2)} -> 43000
A21: Ans 8
B22: {=_xlfn.PERCENTILE.INC(IF(Dataset!L2:L350=Dataset!L326,Dataset!H2:H350),0.2)} -> 48400
A24: Ans 9 | B24: Highest balance for
B25: Stocks | C25: Mutual Funds | D25: Bonds | E25: Real State
B26: =_xlfn.MAXIFS(Dataset!G2:G350,Dataset!L2:L350,Dataset!L2) -> 11000 | C26: =_xlfn.MAXIFS(Dataset!G2:G350,Dataset!L2:L350,Dataset!L4) -> 15000 | D26: =_xlfn.MAXIFS(Dataset!G2:G350,Dataset!L2:L350,Dataset!L3) -> 15000 | E26: =_xlfn.MAXIFS(Dataset!G2:G350,Dataset!L2:L350,Dataset!L5) -> 15000
A28: Ans 10 | B28: Highest annual income for credit card
B29: Premium | C29: Standard
B30: =_xlfn.MAXIFS(Dataset!H2:H350,Dataset!M2:M350,Dataset!M324) -> 82000 | C30: =_xlfn.MAXIFS(Dataset!H2:H350,Dataset!M2:M350,Dataset!M325) -> 74000
B32: People who have not participated in offer
B33: =COUNTIF(Dataset!M2:M350,Dataset!M328) -> 113
A35: Ans 11 | B35: Female account holder in Bank | C35: Second Smallest annual income
B36: =COUNTIF(Dataset!E2:E350,Dataset!E328) -> 170 | C36: {=SMALL(_xlfn.UNIQUE(IF(Dataset!E2:E350="F",Dataset!H2:H350)),2)} -> 47000
A38: Ans 12 | B38: Number of Saving account | C38: Annual income above Median | D38: Highest income in this catogory
B39: =COUNTIF(Dataset!F2:F350,Dataset!F328) -> 160 | C39: =COUNTIFS(Dataset!F2:F350,Dataset!F326,Dataset!H2:H350,">"&MEDIAN(Dataset!H2:H350)) -> 77 | D39: =_xlfn.MAXIFS(Dataset!H2:H350,Dataset!F2:F350,Dataset!F324,Dataset!H2:H350,">"&MEDIAN(Dataset!H2:H350)) -> 80000
A41: Ans 13 | B41: Saving Account total annual income | C41: Largest balance in saving account
B42: =SUMIF(Dataset!F2:F350,Dataset!F328,Dataset!H2:H350) -> 9611000 | C42: =_xlfn.MAXIFS(Dataset!H2:H350,Dataset!F2:F350,Dataset!F328) -> 80000
A44: Ans 14 | C44: Lowest loan amount
B45: =COUNTIFS(Dataset!L2:L350,Dataset!L324,Dataset!M2:M350,Dataset!M326,Dataset!J2:J350,MIN(Dataset!J2:J350)) -> 23 | C45: =_xlfn.MINIFS(Dataset!J2:J350,Dataset!J2:J350,"<>0") -> 5000
